In Python, exception handling is a mechanism to handle run-time errors that occur during the execution of a program. It allows you to catch and handle errors that might occur in your code, rather than allowing them to crash the program.

Python provides a built-in try-except block for exception handling. The try block contains the code that might raise an exception, and the except block contains the code that will handle the exception.

Here's an example of how you might use the try-except block to handle a ZeroDivisionError exception:

```python
try:
    x = 1 / 0
except ZeroDivisionError:
    print("Division by zero is not allowed.")
```

You can also use the finally block, which contains code that will be executed no matter if an exception is raised or not:

```python
try:
    x = 1 / 0
except ZeroDivisionError:
    print("Division by zero is not allowed.")
finally:
    print("This block will always be executed.")
```

You can also use else block which will be executed if there is no exception in the try block.

Copy code
try:
    x = 1 / 2
except ZeroDivisionError:
    print("Division by zero is not allowed.")
else:
    print("No exception occurred.")
You can also catch multiple exception types by providing multiple except block

Copy code
try:
    x = int("hello")
except (ValueError, TypeError):
    print("Invalid input.")
You can also raise an exception explicitly by using the raise keyword.

Copy code
if x < 0:
    raise ValueError("x should be positive.")
Python also provides a built-in assert statement for simple debugging. The assert statement tests a condition, and if the condition is false, it raises an AssertionError exception.

Copy code
x = -1
assert x > 0, "x should be positive"
It's important to note that exception handling should be used judiciously and only to handle exceptional situations that you expect to occur. It's not appropriate to use exception handling to control the flow of normal program execution.

In Python, you can catch all exceptions except specific ones by using the try-except block and providing multiple except clauses, each specifying a different exception to catch.

To catch all exceptions except specific ones, you can use a bare except clause to catch all exceptions, and then provide additional except clauses for the specific exceptions that you do not want to catch.

Here's an example of how you might use this approach to catch all exceptions except ZeroDivisionError:

Copy code
try:
    x = 1 / 0
except ZeroDivisionError:
    print("ZeroDivisionError occurred.")
except:
    print("Some other exception occurred.")
You can also use the Exception class to catch all the exception

Copy code
try:
    x = 1 / 0
except Exception as e:
    if isinstance(e, ZeroDivisionError):
        print("ZeroDivisionError occurred.")
    else:
        print("Other exception occurred.")
It's important to note that the bare except clause should be used with caution, as it can catch unexpected exceptions and lead to unexpected behavior in your program. It's generally recommended to be as specific as possible when catching exceptions and only catch the exceptions that you expect to occur.

It's also important to consider that if you catch an exception and don't handle it, it will suppress the error message and make it harder to troubleshoot issues with the code. It is always a good practice to log the exception and the context in which it occurred, to make it easier to understand what went wrong.

In Python, you can re-throw a caught exception by using the raise keyword without an argument inside the except block.

When you use the raise keyword without an argument, it re-raises the most recent exception that was caught by the current try block.

Here's an example of how you might re-throw a caught exception:

Copy code
try:
    x = 1 / 0
except ZeroDivisionError:
    print("ZeroDivisionError occurred.")
    raise
You can also capture the exception and then re-throw it with a different type or with additional information by passing the caught exception as an argument to the raise statement:

Copy code
try:
    x = 1 / 0
except ZeroDivisionError as e:
    print("ZeroDivisionError occurred.")
    raise ValueError("Math Error") from e
It's important to note that re-throwing exceptions should be used with caution, as it can make it harder to understand the flow of the program and the source of the exception. It's generally recommended to handle the exception in the except block, or to raise a new exception that provides additional context about the problem.

Also, you should not catch an exception if you are not going to handle it or re-throw it. If you catch an exception and don't handle it or re-throw it, it will suppress the error message and make it harder to troubleshoot issues with the code.
